<?xml version="1.0" encoding="utf-8"?>
<!-- =================================================================================== -->
<!-- |    This document was autogenerated by xacro from robots/youbot_gripper_only.urdf.xacro | -->
<!-- |    EDITING THIS FILE BY HAND IS NOT RECOMMENDED                                 | -->
<!-- =================================================================================== -->
<robot name="youbot" xmlns:controller="http://playerstage.sourceforge.net/gazebo/xmlschema/#controller" xmlns:interface="http://playerstage.sourceforge.net/gazebo/xmlschema/#interface" xmlns:sensor="http://playerstage.sourceforge.net/gazebo/xmlschema/#sensor">
  <material name="Orange">
    <color rgba="1.0 0.4 0.0 1.0"/>
  </material>
  <material name="Grey">
    <color rgba="0.7 0.7 0.7 1.0"/>
  </material>
  <material name="DarkGrey">
    <color rgba="0.3 0.3 0.3 1.0"/>
  </material>
  <material name="White">
    <color rgba="1.0 1.0 1.0 1.0"/>
  </material>
  <material name="Black">
    <color rgba="0.0 0.0 0.0 1.0"/>
  </material>
  <material name="Red">
    <color rgba="1.0 0.0 0.0 1.0"/>
  </material>
  <material name="Green">
    <color rgba="0.0 1.0 0.0 1.0"/>
  </material>
  <material name="Blue">
    <color rgba="0.0 0.0 0.8 1.0"/>
  </material>
  <material name="LightGrey">
    <color rgba="0.82 0.82 0.82 1.0"/>
  </material>
  <!-- youbot arm -->
  <!-- xacro:include filename="$(find youbot_description)/urdf/youbot_arm/arm.urdf.xacro" -->
  <!--gazebo>
            <static>true</static>
        </gazebo-->
  <transmission name="trans_gripper_finger_joint_l">
    <type>transmission_interface/SimpleTransmission</type>
    <joint name="gripper_finger_joint_l">
      <hardwareInterface>hardware_interface/EffortJointInterface</hardwareInterface>
    </joint>
    <actuator name="gripper_finger_joint_l_motor">
      <hardwareInterface>hardware_interface/EffortJointInterface</hardwareInterface>
      <mechanicalReduction>1</mechanicalReduction>
    </actuator>
  </transmission>
  <transmission name="trans_gripper_finger_joint_r">
    <type>transmission_interface/SimpleTransmission</type>
    <joint name="gripper_finger_joint_r">
      <hardwareInterface>hardware_interface/EffortJointInterface</hardwareInterface>
    </joint>
    <actuator name="gripper_finger_joint_r_motor">
      <hardwareInterface>hardware_interface/EffortJointInterface</hardwareInterface>
      <mechanicalReduction>1</mechanicalReduction>
    </actuator>
  </transmission>
  <!-- controller manager -->
  <!-- xacro:include filename="$(find youbot_description)/controller/ros_controller.urdf.xacro" /-->
  <!-- Now we can start using the macros included above to define the actual youbot -->
  <!-- The first use of a macro.  This one was defined in base.urdf.xacro above.
       A macro like this will expand to a set of link and joint definitions, and to additional
       Gazebo-related extensions (sensor plugins, etc).  The macro takes an argument, name, 
       that equals "base", and uses it to generate names for its component links and joints 
       (e.g., base_link).  The included origin block is also an argument to the macro.  By convention, 
       the origin block defines where the component is w.r.t its parent (in this case the parent 
       is the world frame). For more, see http://www.ros.org/wiki/xacro -->
  <!-- foot for arm-->
  <!-- link name="base_link">
    <inertial>
		   <origin xyz="0 0 0" rpy="0 0 0"/>
		   <mass value="10.0"/>
		   <inertia ixx="0.1"  ixy="0"  ixz="0" iyy="0.1" iyz="0" izz="0.1" />
    </inertial>
  </link -->
  <!-- xacro:youbot_arm name="arm" parent="base_link">
    <origin xyz="0 0 0" rpy="0 0 0" />
  </xacro:youbot_arm -->
  <!-- joint between arm_7_link and sdh_palm_link -->
  <joint name="gripper_palm_joint" type="fixed">
    <origin rpy="0 0 0" xyz="0 0 0"/>
    <parent link="arm_link_5"/>
    <child link="gripper_palm_link"/>
  </joint>
  <link name="gripper_palm_link">
    <inertial>
      <origin rpy="0 0 0" xyz="0 0 0"/>
      <mass value="0.1"/>
      <inertia ixx="0.01" ixy="0" ixz="0" iyy="0.01" iyz="0" izz="0.01"/>
    </inertial>
    <visual>
      <origin rpy="0 0 0" xyz="0 0 0"/>
      <geometry>
        <mesh filename="package://youbot_description/meshes/youbot_gripper/palm.dae"/>
      </geometry>
      <material name="Black"/>
    </visual>
    <collision>
      <origin rpy="0 0 0" xyz="0 0 0"/>
      <geometry>
        <!--<box size="0.050 0.094 0.054"/>-->
        <mesh filename="package://youbot_description/meshes/youbot_gripper/palm_convex.dae"/>
      </geometry>
    </collision>
  </link>
  <joint name="gripper_finger_joint_l" type="prismatic">
    <origin rpy="0 0 3.14159265359" xyz="0.004 0.008 0.046"/>
    <parent link="gripper_palm_link"/>
    <child link="gripper_finger_link_l"/>
    <axis xyz="0 -1 0"/>
    <dynamics damping="1.0" friction="1.0"/>
    <limit effort="1" lower="0" upper="0.0115" velocity="0.1"/>
    <safety_controller k_position="20" k_velocity="25" soft_lower_limit="0.001" soft_upper_limit="0.011"/>
  </joint>
  <link name="gripper_finger_link_l">
    <inertial>
      <origin rpy="0 0 0" xyz="0 -0.001 0"/>
      <mass value="0.01"/>
      <inertia ixx="0.01" ixy="0" ixz="0" iyy="0.01" iyz="0" izz="0.01"/>
    </inertial>
    <visual>
      <origin rpy="0 0 0" xyz="0 0 0"/>
      <geometry>
        <mesh filename="package://youbot_description/meshes/youbot_gripper/finger.dae"/>
      </geometry>
      <material name="Black"/>
    </visual>
    <collision>
      <origin rpy="0 0 0" xyz="0 0 0"/>
      <geometry>
        <!--<box size="0.014 0.020 0.046"/>-->
        <mesh filename="package://youbot_description/meshes/youbot_gripper/finger_convex.dae"/>
      </geometry>
    </collision>
  </link>
  <joint name="gripper_finger_joint_r" type="prismatic">
    <origin rpy="0 0 0" xyz="0.004 -0.008 0.046"/>
    <parent link="gripper_palm_link"/>
    <child link="gripper_finger_link_r"/>
    <axis xyz="0 -1 0"/>
    <dynamics damping="1.0" friction="1.0"/>
    <limit effort="1" lower="0" upper="0.0115" velocity="0.1"/>
    <safety_controller k_position="20" k_velocity="25" soft_lower_limit="0.001" soft_upper_limit="0.011"/>
  </joint>
  <link name="gripper_finger_link_r">
    <inertial>
      <origin rpy="0 0 0" xyz="0.000 -0.001 0"/>
      <mass value="0.01"/>
      <inertia ixx="0.01" ixy="0" ixz="0" iyy="0.01" iyz="0" izz="0.01"/>
    </inertial>
    <visual>
      <origin rpy="0 0 0" xyz="0 0 0"/>
      <geometry>
        <mesh filename="package://youbot_description/meshes/youbot_gripper/finger.dae"/>
      </geometry>
      <material name="Black"/>
    </visual>
    <collision>
      <origin rpy="0 0 0" xyz="0.000 0 0"/>
      <geometry>
        <!--<box size="0.014 0.020 0.046"/>-->
        <mesh filename="package://youbot_description/meshes/youbot_gripper/finger_convex.dae"/>
      </geometry>
    </collision>
  </link>
  <gazebo reference="gripper_palm_link">
    <material>Gazebo/Black</material>
    <turnGravityOff>false</turnGravityOff>
    <selfCollide>true</selfCollide>
    <sensor name="/youbot_palm_link_contact_sensor" type="contact">
      <always_on>true</always_on>
      <contact>
        <collision>arm_link_5_fixed_joint_lump__gripper_palm_link_collision_1</collision>
      </contact>
      <plugin filename="libgazebo_ros_bumper.so" name="gripper_palm_link_plugin">
        <bumperTopicName>/youbot/palm_link_contact</bumperTopicName>
        <frameName>world</frameName>
      </plugin>
    </sensor>
  </gazebo>
  <gazebo reference="gripper_finger_link_l">
    <material>Gazebo/Grey</material>
    <turnGravityOff>false</turnGravityOff>
    <selfCollide>true</selfCollide>
    <sensor name="/youbot_finger_l_link_contact_sensor" type="contact">
      <always_on>true</always_on>
      <contact>
        <collision>gripper_finger_link_l_collision</collision>
      </contact>
      <plugin filename="libgazebo_ros_bumper.so" name="gripper_finger_l_link_plugin">
        <bumperTopicName>/youbot/finger_l_contact</bumperTopicName>
        <frameName>world</frameName>
      </plugin>
    </sensor>
  </gazebo>
  <gazebo reference="gripper_finger_link_r">
    <material>Gazebo/Grey</material>
    <turnGravityOff>false</turnGravityOff>
    <selfCollide>true</selfCollide>
    <sensor name="/youbot_finger_r_link_contact_sensor" type="contact">
      <always_on>true</always_on>
      <contact>
        <collision>gripper_finger_link_r_collision</collision>
      </contact>
      <plugin filename="libgazebo_ros_bumper.so" name="gripper_finger_r_link_plugin">
        <bumperTopicName>/youbot/finger_r_contact</bumperTopicName>
        <frameName>world</frameName>
      </plugin>
    </sensor>
  </gazebo>
  <transmission name="gripper_finger_l_trans">
    <type>transmission_interface/SimpleTransmission</type>
    <actuator name="gripper_finger_l_motor">
      <hardwareInterface>EffortJointInterface</hardwareInterface>
      <mechanicalReduction>1</mechanicalReduction>
    </actuator>
    <joint name="gripper_finger_joint_l">
      <hardwareInterface>EffortJointInterface</hardwareInterface>
    </joint>
  </transmission>
  <transmission name="gripper_finger_r_trans">
    <type>transmission_interface/SimpleTransmission</type>
    <actuator name="gripper_finger_r_motor">
      <hardwareInterface>EffortJointInterface</hardwareInterface>
      <mechanicalReduction>1</mechanicalReduction>
    </actuator>
    <joint name="gripper_finger_joint_r">
      <hardwareInterface>EffortJointInterface</hardwareInterface>
    </joint>
  </transmission>
</robot>

